2020-09-10 01:26:46,827 ERROR: Exception on /addmatch/Power Grid/7 [GET] [in /home/philipp/Documents/bgl/venv/lib/python3.6/site-packages/flask/app.py:1892]
Traceback (most recent call last):
  File "/home/philipp/Documents/bgl/venv/lib/python3.6/site-packages/flask/app.py", line 2447, in wsgi_app
    response = self.full_dispatch_request()
  File "/home/philipp/Documents/bgl/venv/lib/python3.6/site-packages/flask/app.py", line 1952, in full_dispatch_request
    rv = self.handle_user_exception(e)
  File "/home/philipp/Documents/bgl/venv/lib/python3.6/site-packages/flask/app.py", line 1821, in handle_user_exception
    reraise(exc_type, exc_value, tb)
  File "/home/philipp/Documents/bgl/venv/lib/python3.6/site-packages/flask/_compat.py", line 39, in reraise
    raise value
  File "/home/philipp/Documents/bgl/venv/lib/python3.6/site-packages/flask/app.py", line 1950, in full_dispatch_request
    rv = self.dispatch_request()
  File "/home/philipp/Documents/bgl/venv/lib/python3.6/site-packages/flask/app.py", line 1936, in dispatch_request
    return self.view_functions[rule.endpoint](**req.view_args)
  File "/home/philipp/Documents/bgl/venv/lib/python3.6/site-packages/flask_login/utils.py", line 272, in decorated_view
    return func(*args, **kwargs)
  File "/home/philipp/Documents/bgl/app/routes.py", line 97, in addmatch
    form = LocalForm()
  File "/home/philipp/Documents/bgl/venv/lib/python3.6/site-packages/wtforms/form.py", line 208, in __call__
    return type.__call__(cls, *args, **kwargs)
  File "/home/philipp/Documents/bgl/venv/lib/python3.6/site-packages/flask_wtf/form.py", line 87, in __init__
    super(FlaskForm, self).__init__(formdata=formdata, **kwargs)
  File "/home/philipp/Documents/bgl/venv/lib/python3.6/site-packages/wtforms/form.py", line 274, in __init__
    self.process(formdata, obj, data=data, **kwargs)
  File "/home/philipp/Documents/bgl/venv/lib/python3.6/site-packages/wtforms/form.py", line 131, in process
    field.process(formdata)
  File "/home/philipp/Documents/bgl/venv/lib/python3.6/site-packages/wtforms/fields/core.py", line 960, in process
    self._add_entry(formdata)
  File "/home/philipp/Documents/bgl/venv/lib/python3.6/site-packages/wtforms/fields/core.py", line 1020, in _add_entry
    'You cannot have more than max_entries entries in this FieldList'
AssertionError: You cannot have more than max_entries entries in this FieldList
2020-09-10 01:44:42,327 INFO: BGL Stats [in /home/philipp/Documents/bgl/app/__init__.py:34]
2020-09-10 01:47:09,135 INFO: BGL Stats [in /home/philipp/Documents/bgl/app/__init__.py:34]
2020-09-10 01:47:12,784 ERROR: Exception on /addmatch/Power Grid/3 [POST] [in /home/philipp/Documents/bgl/venv/lib/python3.6/site-packages/flask/app.py:1892]
Traceback (most recent call last):
  File "/home/philipp/Documents/bgl/venv/lib/python3.6/site-packages/flask/app.py", line 2447, in wsgi_app
    response = self.full_dispatch_request()
  File "/home/philipp/Documents/bgl/venv/lib/python3.6/site-packages/flask/app.py", line 1952, in full_dispatch_request
    rv = self.handle_user_exception(e)
  File "/home/philipp/Documents/bgl/venv/lib/python3.6/site-packages/flask/app.py", line 1821, in handle_user_exception
    reraise(exc_type, exc_value, tb)
  File "/home/philipp/Documents/bgl/venv/lib/python3.6/site-packages/flask/_compat.py", line 39, in reraise
    raise value
  File "/home/philipp/Documents/bgl/venv/lib/python3.6/site-packages/flask/app.py", line 1950, in full_dispatch_request
    rv = self.dispatch_request()
  File "/home/philipp/Documents/bgl/venv/lib/python3.6/site-packages/flask/app.py", line 1936, in dispatch_request
    return self.view_functions[rule.endpoint](**req.view_args)
  File "/home/philipp/Documents/bgl/venv/lib/python3.6/site-packages/flask_login/utils.py", line 272, in decorated_view
    return func(*args, **kwargs)
  File "/home/philipp/Documents/bgl/app/routes.py", line 99, in addmatch
    match = Match(game=game.id, stats=form.to_dict(flat=False))
AttributeError: 'LocalForm' object has no attribute 'to_dict'
2020-09-10 01:47:33,558 INFO: BGL Stats [in /home/philipp/Documents/bgl/app/__init__.py:34]
2020-09-10 01:48:21,959 INFO: BGL Stats [in /home/philipp/Documents/bgl/app/__init__.py:34]
2020-09-10 01:48:55,957 INFO: BGL Stats [in /home/philipp/Documents/bgl/app/__init__.py:34]
2020-09-10 01:50:30,436 INFO: BGL Stats [in /home/philipp/Documents/bgl/app/__init__.py:34]
2020-09-10 01:54:27,634 INFO: BGL Stats [in /home/philipp/Documents/bgl/app/__init__.py:34]
2020-09-10 01:54:29,616 ERROR: Exception on /addmatch/Power Grid/3 [POST] [in /home/philipp/Documents/bgl/venv/lib/python3.6/site-packages/flask/app.py:1892]
Traceback (most recent call last):
  File "/home/philipp/Documents/bgl/venv/lib/python3.6/site-packages/flask/app.py", line 2447, in wsgi_app
    response = self.full_dispatch_request()
  File "/home/philipp/Documents/bgl/venv/lib/python3.6/site-packages/flask/app.py", line 1952, in full_dispatch_request
    rv = self.handle_user_exception(e)
  File "/home/philipp/Documents/bgl/venv/lib/python3.6/site-packages/flask/app.py", line 1821, in handle_user_exception
    reraise(exc_type, exc_value, tb)
  File "/home/philipp/Documents/bgl/venv/lib/python3.6/site-packages/flask/_compat.py", line 39, in reraise
    raise value
  File "/home/philipp/Documents/bgl/venv/lib/python3.6/site-packages/flask/app.py", line 1950, in full_dispatch_request
    rv = self.dispatch_request()
  File "/home/philipp/Documents/bgl/venv/lib/python3.6/site-packages/flask/app.py", line 1936, in dispatch_request
    return self.view_functions[rule.endpoint](**req.view_args)
  File "/home/philipp/Documents/bgl/venv/lib/python3.6/site-packages/flask_login/utils.py", line 272, in decorated_view
    return func(*args, **kwargs)
  File "/home/philipp/Documents/bgl/app/routes.py", line 99, in addmatch
    scores = form.data.scores
AttributeError: 'dict' object has no attribute 'scores'
2020-09-10 01:54:50,634 INFO: BGL Stats [in /home/philipp/Documents/bgl/app/__init__.py:34]
2020-09-10 01:56:09,192 INFO: BGL Stats [in /home/philipp/Documents/bgl/app/__init__.py:34]
2020-09-10 01:58:23,873 INFO: BGL Stats [in /home/philipp/Documents/bgl/app/__init__.py:34]
2020-09-10 01:59:00,616 INFO: BGL Stats [in /home/philipp/Documents/bgl/app/__init__.py:34]
2020-09-10 01:59:19,726 INFO: BGL Stats [in /home/philipp/Documents/bgl/app/__init__.py:34]
2020-09-10 02:00:31,843 INFO: BGL Stats [in /home/philipp/Documents/bgl/app/__init__.py:34]
